============================= test session starts ==============================
platform linux -- Python 3.9.20, pytest-7.4.0, pluggy-1.0.0 -- /home/dk.busimanager/code/donat-konan33/StreamingAnalytics/.venv/bin/python
cachedir: .pytest_cache
rootdir: /home/dk.busimanager/code/donat-konan33/StreamingAnalytics
collecting ... collected 0 items / 1 error

==================================== ERRORS ====================================
______________________ ERROR collecting tests/test_all.py ______________________
.venv/lib/python3.9/site-packages/pandas/core/internals/construction.py:982: in _finalize_columns_and_data
    columns = _validate_or_indexify_columns(contents, columns)
.venv/lib/python3.9/site-packages/pandas/core/internals/construction.py:1030: in _validate_or_indexify_columns
    raise AssertionError(
E   AssertionError: 3 columns passed, passed data had 2 columns

The above exception was the direct cause of the following exception:
.venv/lib/python3.9/site-packages/_pytest/runner.py:341: in from_call
    result: Optional[TResult] = func()
.venv/lib/python3.9/site-packages/_pytest/runner.py:372: in <lambda>
    call = CallInfo.from_call(lambda: list(collector.collect()), "collect")
.venv/lib/python3.9/site-packages/_pytest/python.py:531: in collect
    self._inject_setup_module_fixture()
.venv/lib/python3.9/site-packages/_pytest/python.py:545: in _inject_setup_module_fixture
    self.obj, ("setUpModule", "setup_module")
.venv/lib/python3.9/site-packages/_pytest/python.py:310: in obj
    self._obj = obj = self._getobj()
.venv/lib/python3.9/site-packages/_pytest/python.py:528: in _getobj
    return self._importtestmodule()
.venv/lib/python3.9/site-packages/_pytest/python.py:617: in _importtestmodule
    mod = import_path(self.path, mode=importmode, root=self.config.rootpath)
.venv/lib/python3.9/site-packages/_pytest/pathlib.py:565: in import_path
    importlib.import_module(module_name)
../../../.pyenv/versions/3.9.20/lib/python3.9/importlib/__init__.py:127: in import_module
    return _bootstrap._gcd_import(name[level:], package, level)
<frozen importlib._bootstrap>:1030: in _gcd_import
    ???
<frozen importlib._bootstrap>:1007: in _find_and_load
    ???
<frozen importlib._bootstrap>:986: in _find_and_load_unlocked
    ???
<frozen importlib._bootstrap>:680: in _load_unlocked
    ???
.venv/lib/python3.9/site-packages/_pytest/assertion/rewrite.py:178: in exec_module
    exec(co, module.__dict__)
tests/test_all.py:3: in <module>
    import lwqueue.clickhouse_queries as student_queries
lwqueue/clickhouse_queries.py:97: in <module>
    top_users_df = pd.DataFrame(get_top_active_users(), columns=columns)
.venv/lib/python3.9/site-packages/pandas/core/frame.py:721: in __init__
    arrays, columns, index = nested_data_to_arrays(
.venv/lib/python3.9/site-packages/pandas/core/internals/construction.py:519: in nested_data_to_arrays
    arrays, columns = to_arrays(data, columns, dtype=dtype)
.venv/lib/python3.9/site-packages/pandas/core/internals/construction.py:883: in to_arrays
    content, columns = _finalize_columns_and_data(arr, columns, dtype)
.venv/lib/python3.9/site-packages/pandas/core/internals/construction.py:985: in _finalize_columns_and_data
    raise ValueError(err) from err
E   ValueError: 3 columns passed, passed data had 2 columns
=========================== short test summary info ============================
ERROR tests/test_all.py - ValueError: 3 columns passed, passed data had 2 col...
!!!!!!!!!!!!!!!!!!!! Interrupted: 1 error during collection !!!!!!!!!!!!!!!!!!!!
======================== 2 warnings, 1 error in 12.51s =========================
